Workbook

Sheet Start
A1: Akquise Neunkirchen, Version 2 (Stand 19.10.2026)
A2: Gelbe Felder ausfüllen. Alle Brief- und Mailtexte im Blatt 'Outreach' setzen sich daraus automatisch zusammen.
A4: Absender | B4: Jean | C4: Ihr voller Name, so wie er unter Brief und Mail stehen soll
A5: Telefon | C5: Mobilnummer für Anruf und WhatsApp
A6: Absender_Web | C6: Eigene Website oder Vorschau-Domain, nicht die Arbeitgeber-Domain
A7: Absender_Mail | C7: Eigene Geschäftsadresse, nicht die Arbeitgeber-Adresse
A8: Vorschau_Link | C8: Standard-Link zur Vorschau, falls im Outreach-Blatt kein eigener Link steht
A9: Termin_Vorschlag | B9: Donnerstag gegen 15 Uhr | C9: Konkreter Terminvorschlag für M1, M2, W1
A10: Referenzpreis_Datum | B10: 30.11.2026 | C10: Bis wann der Referenzpreis gilt (F3)
A11: Bewertungslink | C11: Kurzlink zu Ihrem Google-Profil zum Bewerten (R1)
A12: Empfehlungsbonus | B12: einem Gutschein über 50 € | C12: Dankeschön für Empfehlungen (R1)
A14: So nutzen Sie die Datei:
A15: 1. Blatt 'Outreach' nach Spalte 'Welle' filtern. Welle 1 sind die stärksten Leads mit belegbarem Aufhänger.
A16: 2. Erstkontakt per Brief (Spalte 'Brief-Text') oder persönlich. Vor dem Versand die Website einmal am Handy öffnen und den Aufhänger kurz gegenprüfen.
A17: 3. E-Mail und WhatsApp erst, wenn der Betrieb zugestimmt hat: im Gespräch, per Antwort auf den Brief oder per Rückruf. Ohne Einwilligung ist Werbung per E-Mail auch an Firmen nach § 7 Abs. 2 UWG unzulässig und abmahnfähig.
A18: 4. Status, Datum und Kanal pflegen. Spalte 'Nächster Schritt fällig' rechnet die Nachfass-Termine (Tag 3, 7, 14) selbst aus.
A19: 5. Texte ändern Sie zentral im Blatt 'Vorlagen'. Platzhalter in geschweiften Klammern bleiben stehen.

Sheet Vorlagen
A1: ID | B1: Name | C1: Kanal und Rechtsrahmen | D1: Zeitpunkt | E1: Betreff | F1: Text
A2: B1 | B2: Brief Erstkontakt (ohne fertige Vorschau) | C2: Brief, kalt, rechtlich unkritisch | D2: Tag 0 | E2: {Betrieb}: Ihre Website auf dem Handy | F2: {Anrede} ich bin {Absender}, Webdesigner und KI-Berater hier in Neunkirchen. Ich habe mir {Domain} auf dem Handy angesehen. Dabei ist mir aufgefallen: {Hook1} {Winkel} Deshalb ein Vorschlag: Ich baue Ihnen eine Vorschau Ihrer neuen Startseite, mit Ihren eigenen Texten und Fotos. Das kostet Sie nichts und verpflichtet Sie zu nichts. Ich bringe sie vorbei, Sie schauen sie in Ruhe an. Gefällt sie Ihnen nicht, war es das. Ein kurzes Ja genügt: QR-Code scannen, anrufen oder per WhatsApp schreiben an {Telefon}. Falls Sie danach umsteigen möchten: Eine neue Website kostet bei mir {Preis}, die Betreuung {Monat} im Monat. Für Betriebe wie Ihren lohnt sich oft zusätzlich {Extra}. Viele Grüße aus Neunkirchen {Absender} {Absender_Web} P.S. {Hook2} Ihre Anschrift stammt aus Ihrem Impressum bzw. öffentlichen Branchenverzeichnissen. Wenn Sie keine Post mehr von mir möchten, genügt ein kurzer Hinweis.
A3: B2 | B3: Brief Erstkontakt (Vorschau liegt bei) | C3: Brief, kalt, mit A4 Vorher/Nachher als Anlage | D3: Tag 0 | E3: {Betrieb}: so könnte Ihre Website aussehen | F3: {Anrede} ich bin {Absender}, Webdesigner und KI-Berater hier in Neunkirchen. Ich habe Ihre Startseite einmal neu gestaltet, mit Ihren eigenen Texten und Fotos. Das Ergebnis liegt bei: links Ihre Seite heute, rechts der Entwurf. Warum ich mich melde: {Hook1} {Winkel} Der Entwurf ist fertig. Ob Sie ihn nutzen, entscheiden Sie. Wenn Sie ihn auf Ihrem Handy sehen möchten, scannen Sie den QR-Code oder schreiben Sie mir per WhatsApp an {Telefon}. Ich komme auch gern für 15 Minuten vorbei. Damit Sie nicht raten müssen: {Preis} einmalig, Betreuung {Monat} im Monat. Die zweite Hälfte zahlen Sie erst, wenn die Seite online ist und Ihnen gefällt. Viele Grüße aus Neunkirchen {Absender} {Absender_Web} P.S. {Hook2} Ihre Anschrift stammt aus Ihrem Impressum bzw. öffentlichen Branchenverzeichnissen. Wenn Sie keine Post mehr von mir möchten, genügt ein kurzer Hinweis.
A4: B3 | B4: Brief für Betriebe ohne eigene Website | C4: Brief, kalt, rechtlich unkritisch | D4: Tag 0 | E4: {Betrieb}: Ihre Kunden suchen Sie bei Google | F4: {Anrede} ich bin {Absender}, Webdesigner und KI-Berater hier in Neunkirchen. Wer {Betrieb} bei Google sucht, landet heute auf Facebook oder in einem Branchenverzeichnis. Öffnungszeiten, Angebot und ein direkter Weg zu Ihnen fehlen dort oft oder sind veraltet. Mein Vorschlag: Ich baue Ihnen eine einfache, schnelle Website mit Ihren eigenen Fotos und Texten. Vorher sehen Sie eine Vorschau, kostenlos und unverbindlich. Ein kurzes Ja genügt: QR-Code scannen, anrufen oder per WhatsApp schreiben an {Telefon}. Eine erste Website kostet bei mir ab 590 €, die Betreuung ab 29 € im Monat. Ihr Google-Profil richte ich auf Wunsch gleich mit ein. Viele Grüße aus Neunkirchen {Absender} {Absender_Web} P.S. Die Vorschau bleibt auch dann kostenlos, wenn Sie sich am Ende dagegen entscheiden. Ihre Anschrift stammt aus Ihrem Impressum bzw. öffentlichen Branchenverzeichnissen. Wenn Sie keine Post mehr von mir möchten, genügt ein kurzer Hinweis.
A5: M1 | B5: E-Mail nach Besuch (Vorschau-Mail) | C5: E-Mail, nur nach Einwilligung im Gespräch | D5: Tag 0, am selben Tag | E5: {Betrieb}: Ihre Vorschau von heute | F5: {Anrede} danke für die paar Minuten heute. Wie besprochen hier die Vorschau für {Betrieb}: {Vorschau_Link} Öffnen Sie sie am besten auf dem Handy, so sehen Ihre Kunden die Seite auch. Kurz zusammengefasst: - Heute: {Hook1} - Neu: Alles ist auf das Handy ausgelegt, dazu {Extra}. - Ihre Inhalte bleiben. Sie müssen nichts neu schreiben. Preis: {Preis} einmalig, Betreuung {Monat} im Monat. Die zweite Hälfte zahlen Sie erst nach dem Livegang. Nächster Schritt: 15 Minuten, in denen wir Fotos und zwei, drei Wünsche durchgehen. Passt Ihnen {Termin_Vorschlag}? Viele Grüße {Absender} {Telefon} Wenn Sie keine weiteren Nachrichten von mir möchten, genügt eine kurze Antwort.
A6: M2 | B6: Antwort auf Rückmeldung zum Brief | C6: E-Mail, Einwilligung liegt durch Rückmeldung vor | D6: innerhalb von 2 Stunden | E6: Re: Vorschau für {Betrieb} | F6: {Anrede} schön, dass Sie sich melden. Ich baue die Vorschau jetzt und schicke sie Ihnen bis {Termin_Vorschlag}. Damit sie möglichst echt aussieht, zwei kurze Fragen: 1. Haben Sie ein paar aktuelle Fotos (Laden, Team, Produkte)? Handyfotos reichen. 2. Was soll ein Besucher auf Ihrer Seite als Erstes tun: anrufen, buchen, bestellen oder vorbeikommen? Wenn Sie dafür gerade keine Zeit haben, nehme ich einfach die Inhalte Ihrer jetzigen Seite. Viele Grüße {Absender} {Telefon}
A7: F1 | B7: Nachfassen 1: Vorschau angesehen? | C7: E-Mail oder WhatsApp, nach Einwilligung | D7: Tag 3 | E7: Re: {Betrieb}: Ihre Vorschau von heute | F7: {Anrede} kurz nachgefragt: Konnten Sie die Vorschau schon auf dem Handy ansehen? {Vorschau_Link} Wenn Sie mögen, setze ich bis Ende der Woche Ihre eigenen Fotos ein. Dann sehen Sie die Seite so, wie sie online gehen würde. Ein kurzes "Ja, machen" genügt. Viele Grüße {Absender} Wenn Sie keine weiteren Nachrichten von mir möchten, genügt eine kurze Antwort.
A8: F2 | B8: Nachfassen 2: Tipp mit Mehrwert | C8: E-Mail, nach Einwilligung | D8: Tag 7 | E8: Ein Tipp für {Betrieb}, auch ohne mich | F8: {Anrede} unabhängig davon, ob wir zusammenarbeiten, hier ein Tipp, der in fünf Minuten erledigt ist: {Tipp} Die Vorschau Ihrer neuen Seite liegt weiter für Sie bereit: {Vorschau_Link} Bei Fragen rufen Sie mich einfach an: {Telefon} Viele Grüße {Absender} Wenn Sie keine weiteren Nachrichten von mir möchten, genügt eine kurze Antwort.
A9: F3 | B9: Nachfassen 3: Abschluss | C9: E-Mail, nach Einwilligung | D9: Tag 14 | E9: Soll ich die Vorschau für {Betrieb} behalten? | F9: {Anrede} ich möchte Ihr Postfach nicht füllen, deshalb ist das meine letzte Nachricht dazu. Den Referenzpreis halte ich für Sie bis {Referenzpreis_Datum}. Danach nehme ich die Vorschau aus dem Netz. Eine Ziffer als Antwort genügt mir: 1 = Ja, lassen Sie uns kurz sprechen 2 = Später, melden Sie sich im neuen Jahr 3 = Kein Interesse Danke und viele Grüße {Absender}
A10: W1 | B10: WhatsApp nach Besuch | C10: WhatsApp, nur wenn Nummer im Gespräch dafür gegeben | D10: Tag 0, direkt nach Besuch | F10: Hallo, hier ist {Absender} von vorhin. Hier die Vorschau für {Betrieb}, am besten gleich auf dem Handy öffnen: {Vorschau_Link} Ich melde mich {Termin_Vorschlag} kurz wegen der Fotos. Viele Grüße
A11: A1 | B11: Angebots-Mail | C11: E-Mail nach Gespräch | D11: Tag des Gesprächs | E11: Angebot neue Website {Betrieb} | F11: {Anrede} wie besprochen hier Ihr Angebot. Die Kurzfassung: - Neue Website auf Basis der Vorschau: {Preis} - Dazu: {Extra} - Betreuung mit Hosting, Updates und kleinen Änderungen: {Monat} im Monat - Zahlung: 50 % bei Auftrag, 50 % nach Livegang - Livegang: etwa zwei Wochen, nachdem Sie Fotos und Texte freigegeben haben Wenn das für Sie passt, antworten Sie einfach mit "Einverstanden". Dann lege ich los. Viele Grüße {Absender} {Telefon}
A12: R1 | B12: Nach Livegang: Bewertung und Empfehlung | C12: E-Mail an Kunden | D12: 1 Woche nach Livegang | E12: Danke, und eine kleine Bitte | F12: {Anrede} Ihre neue Seite ist online, danke für die gute Zusammenarbeit. Zwei kleine Bitten: 1. Wenn Sie zufrieden sind, freue ich mich über eine ehrliche Google-Bewertung: {Bewertungslink} 2. Kennen Sie einen Betrieb in Neunkirchen, dem das auch helfen würde? Für jede Empfehlung, aus der ein Auftrag wird, bedanke ich mich mit {Empfehlungsbonus}. Viele Grüße {Absender}

Sheet Gesamtliste
A1: Rang | B1: Betrieb | C1: Branche | D1: Segment | E1: Adresse | F1: Telefon | G1: Website | H1: Prüfstatus | I1: HTTPS | J1: Mobil | K1: Ladezeit s | L1: CMS | M1: Letzte Änderung | N1: Facebook | O1: Instagram | P1: Strukt. Daten | Q1: Buchung/Bestellung | R1: Google Ø | S1: Google Anzahl | T1: A Modernisierung (0-40) | U1: B Einfachheit (0-20) | V1: C Potenzial (0-25) | W1: D Lücken (0-15) | X1: Gesamt | Y1: Label | Z1: Liste | AA1: Inhaber/in | AB1: E-Mail | AC1: Impressum
A2: 1 | B2: Asia Wok Bistro | C2: Restaurant (asiatisch) | D2: Gastronomie | E2: Brückenstr. 26, 66538 Neunkirchen | F2: 06821 140373 | G2: https://asia-wok-neunkirchen.de/speisekarte | H2: live | I2: ja | J2: nein | K2: 4.6 | N2: nein | O2: nein | P2: nein | Q2: nein | R2: 4.4 | S2: 230 | T2: 28 | U2: 15 | V2: 24 | W2: 10 | X2: =SUM(T2:W2) -> 77 | Y2: Umsatzhebel | Z2: Liste 1
A3: 2 | B3: Schlüssel Thielen | C3: Schlüsseldienst | D3: Handel/Dienstleistung | E3: Hüttenbergstr. 30, 66538 Neunkirchen | F3: 06821 22510 | G3: https://www.schluessel-thielen.de/ | H3: live | I3: ja | J3: nein | K3: 11.1 | M3: Wed, 10 Jul 2024 08:33:35 GMT | N3: nein | O3: nein | P3: nein | Q3: nein | R3: 4.6 | S3: 15 | T3: 30 | U3: 16 | V3: 17 | W3: 13 | X3: =SUM(T3:W3) -> 76 | Y3: Quick Win | Z3: Liste 1 | AB3: info@schluessel-thielen.de | AC3: https://www.schluessel-thielen.de/Kontakt.htm
A4: 3 | B4: L.A.-Nails Nagelstudio | C4: Nagelstudio | D4: Beauty/Körperpflege | E4: Stummplatz 1, 66538 Neunkirchen | F4: 06821 1 79 91 52 | G4: https://www.la-nails.de/lander | H4: live | I4: ja | J4: ja | K4: 0.7 | N4: nein | O4: nein | P4: nein | Q4: nein | R4: 4.3 | S4: 48 | T4: 30 | U4: 17 | V4: 19 | W4: 10 | X4: =SUM(T4:W4) -> 76 | Y4: Quick Win | Z4: Liste 2
A5: 4 | B5: Dolomiti Pizzeria, Gelateria & Pasticceria | C5: Pizzeria/Eiscafé | D5: Lieferdienst/Imbiss | E5: Oberer Markt 10, 66538 Neunkirchen | F5: 06821 9424024 | G5: https://www.dolomitipizzeria-neunkirchen.de/ | H5: live | I5: ja | J5: nein | K5: 2.2 | N5: nein | O5: nein | P5: nein | Q5: ja | R5: 4.3 | S5: 358 | T5: 28 | U5: 16 | V5: 25 | W5: 7 | X5: =SUM(T5:W5) -> 76 | Y5: Umsatzhebel | Z5: Liste 2
A6: 5 | B6: Nieland Julia Pasta | C6: Partyservice | D6: Gastronomie | E6: Waldwiesenstr. 4, 66538 Neunkirchen | F6: 0171 1 04 21 12 | G6: https://www.pastaria-by-julie.de/ | H6: live | I6: ja | J6: nein | K6: 1.3 | M6: Wed, 30 Sep 2020 13:48:44 GMT | N6: nein | O6: nein | P6: nein | Q6: nein | T6: 33 | U6: 15 | V6: 17 | W6: 10 | X6: =SUM(T6:W6) -> 75 | Y6: Umsatzhebel | Z6: Liste 2
A7: 6 | B7: Wibilo-Kebap-Haus | C7: Döner/Kebab | D7: Lieferdienst/Imbiss | E7: Wibilostr. 12, 66540 Neunkirchen | F7: 06821 9533808 | G7: https://www.wibilo-kebap-haus.de/ | H7: live | I7: ja | J7: nein | K7: 2.1 | N7: nein | O7: nein | P7: nein | Q7: ja | R7: 3.2 | S7: 232 | T7: 28 | U7: 16 | V7: 21 | W7: 10 | X7: =SUM(T7:W7) -> 75 | Y7: Umsatzhebel | Z7: Liste 2
A8: 7 | B8: Pizza Heimservice Gondoliere | C8: Pizzeria/Lieferdienst | D8: Lieferdienst/Imbiss | E8: Storchenplatz 1, 66538 Neunkirchen | F8: 06821 13212 | G8: https://gondoliere-neunkirchen.de/ | H8: live | I8: ja | J8: ja | K8: 21.8 | L8: WordPress 7.1.3 | N8: nein | O8: nein | P8: nein | Q8: nein | R8: 4 | S8: 174 | T8: 24 | U8: 16 | V8: 25 | W8: 10 | X8: =SUM(T8:W8) -> 75 | Y8: Umsatzhebel | Z8: Liste 1 | AA8: Carmen Abbruzzino | AB8: info@gondoliere-neunkirchen.de | AC8: https://gondoliere-neunkirchen.de/impressum/
A9: 8 | B9: Didié Hermann Zeichen- und Bürobedarf | C9: Schreib- und Bürobedarf | D9: Handel/Dienstleistung | E9: Bahnhofstr. 1 c, 66538 Neunkirchen | F9: 06821 2 27 57 | G9: https://www.hermann-didie.de/ | H9: live | I9: ja | J9: nein | K9: 7.5 | M9: Fri, 11 Feb 2011 15:11:25 GMT | N9: nein | O9: nein | P9: nein | Q9: nein | R9: 4.6 | S9: 190 | T9: 27 | U9: 16 | V9: 21 | W9: 10 | X9: =SUM(T9:W9) -> 74 | Y9: Quick Win | Z9: Liste 2
A10: 9 | B10: Beauty Nails Ornella | C10: Nagelstudio | D10: Beauty/Körperpflege | E10: Ruhstockstr. 10, 66538 Neunkirchen | F10: 06821 4013600 | G10: https://www.beauty-nails-ornella.de/ | H10: live | I10: ja | J10: nein | K10: 13 | M10: Mon, 21 May 2012 16:40:53 GMT | N10: nein | O10: nein | P10: nein | Q10: nein | T10: 30 | U10: 17 | V10: 16 | W10: 10 | X10: =SUM(T10:W10) -> 73 | Y10: Quick Win | Z10: Liste 1
A11: 10 | B11: MDM MetallDesignMüller / Innovativer Metallbau / Inh.: Christian Müller-Metallbaumeister | C11: Metallbau | D11: Handwerk/Bau | E11: Mozartstr. 7-9, 66538 Neunkirchen | F11: 06821 1 79 97 57 | G11: https://www.metalldesignmueller.de/ | H11: live | I11: ja | J11: nein | K11: 4.1 | M11: Fri, 28 Sep 2018 17:25:03 GMT | N11: nein | O11: nein | P11: nein | Q11: nein | R11: 3.7 | S11: 9 | T11: 29 | U11: 16 | V11: 14 | W11: 13 | X11: =SUM(T11:W11) -> 72 | Y11: Quick Win | Z11: Liste 2
A12: 11 | B12: aqua bar lounge club | C12: Bar/Club | D12: Gastronomie | E12: Jahnstr. 2, 66538 Neunkirchen | F12: 06821 8681999 | G12: https://aqua-nk.de/ | H12: live | I12: ja | J12: ja | K12: 4.1 | M12: Mon, 11 Nov 2024 21:11:07 GMT | N12: ja | O12: nein | P12: nein | Q12: nein | S12: 0 | T12: 30 | U12: 15 | V12: 17 | W12: 9 | X12: =SUM(T12:W12) -> 71 | Y12: Umsatzhebel | Z12: Liste 1
A13: 12 | B13: Krankengymnastik Rutz | C13: Physiotherapie | D13: Praxis/Gesundheit | E13: Max-Braun-Str. 1, 66538 Neunkirchen | F13: 06821 23665 | G13: https://www.krankengymnastik-rutz.de/ | H13: live | I13: ja | J13: nein | K13: 8.6 | M13: Tue, 12 Jan 2021 12:41:50 GMT | N13: nein | O13: nein | P13: nein | Q13: nein | R13: 5 | S13: 2 | T13: 30 | U13: 13 | V13: 15 | W13: 13 | X13: =SUM(T13:W13) -> 71 | Y13: Solide Chance | Z13: Liste 1 | AA13: Hermann Rutz | AB13: hermannrutz@t-online.de | AC13: https://www.krankengymnastik-rutz.de/impressum.html
A14: 13 | B14: Schreiner Barbara Fotostudio | C14: Fotostudio | D14: Handel/Dienstleistung | E14: Lantertalweg 2, 66539 Neunkirchen | F14: 06821 39 93 | G14: https://fotostudio-schreiner.de/ | H14: live | I14: ja | J14: ja | K14: 3 | M14: Tue, 08 Sep 2026 22:14:20 GMT | N14: nein | O14: nein | P14: nein | Q14: nein | R14: 4.5 | S14: 55 | T14: 30 | U14: 16 | V14: 15 | W14: 10 | X14: =SUM(T14:W14) -> 71 | Y14: Quick Win | Z14: Liste 2
A15: 14 | B15: Aktiv Gesundheitspark | C15: Gesundheitssport/Reha | D15: Handel/Dienstleistung | E15: Vogelstr. 4, 66538 Neunkirchen | F15: 06821 91 96 62 | G15: https://www.aktiv-gesundheitspark.de/ | H15: live | I15: ja | J15: ja | K15: 3 | N15: nein | O15: nein | P15: nein | Q15: nein | T15: 30 | U15: 16 | V15: 14 | W15: 10 | X15: =SUM(T15:W15) -> 70 | Y15: Quick Win | Z15: Liste 2
A16: 15 | B16: Heil Schlosserei GmbH | C16: Schlosserei/Metallbau | D16: Handwerk/Bau | E16: Eichendorffstr. 4, 66540 Neunkirchen | F16: 06821 5 13 62 | G16: https://www.schlosserei-heil.de/ | H16: live | I16: ja | J16: nein | K16: 8.2 | L16: CMSimple 3.2 | N16: nein | O16: nein | P16: nein | Q16: nein | R16: 2.7 | S16: 12 | T16: 27 | U16: 16 | V16: 14 | W16: 13 | X16: =SUM(T16:W16) -> 70 | Y16: Quick Win | Z16: Liste 2 | AA16: Bernd Heil | AB16: info@schlosserei-heil.de | AC16: https://www.schlosserei-heil.de/?Impressum
A17: 16 | B17: Ratzky GmbH Bedachungen | C17: Dachdecker | D17: Handwerk/Bau | E17: Sebachstr. 23, 66539 Neunkirchen | F17: 06821 9 30 10 | G17: https://www.ratzkygmbh.de/ | H17: live | I17: ja | J17: nein | K17: 3.7 | M17: Tue, 19 Mar 2019 10:33:29 GMT | N17: nein | O17: nein | P17: nein | Q17: nein | R17: 4.1 | S17: 14 | T17: 27 | U17: 16 | V17: 14 | W17: 13 | X17: =SUM(T17:W17) -> 70 | Y17: Quick Win | Z17: Liste 2 | AA17: Reiner Ratzky | AB17: info@ratzkygmbh.de | AC17: https://www.ratzkygmbh.de/impressum.html
A18: 17 | B18: High Voltage | C18: Elektriker | D18: Handwerk/Bau | E18: An der Alten Ziegelei 25, 66538 Neunkirchen | F18: 06821 98 31 61 | G18: https://www.hvoltage.de/ | H18: live | I18: ja | J18: nein | K18: 5.1 | L18: TYPO3 4.5 CMS | N18: nein | O18: nein | P18: nein | Q18: nein | R18: 4.8 | S18: 4 | T18: 26 | U18: 16 | V18: 14 | W18: 13 | X18: =SUM(T18:W18) -> 69 | Y18: Quick Win | Z18: Liste 2 | AB18: mg@hvoltage.de | AC18: https://www.hvoltage.de/index.php?id=17
A19: 18 | B19: Orient Grill | C19: Imbiss/Döner | D19: Lieferdienst/Imbiss | E19: Oberer Markt 13, 66538 Neunkirchen | F19: 06821 8692053 | G19: http://www.orientgrill-nk.de/ | H19: nur HTTP | I19: nein | J19: ? | K19: 1.6 | N19: nein | O19: nein | P19: nein | Q19: nein | R19: 4.2 | S19: 616 | T19: 22 | U19: 16 | V19: 25 | W19: 6 | X19: =SUM(T19:W19) -> 69 | Y19: Nicht prüfbar | Z19: Liste 1
A20: 19 | B20: Rümpel Alf | C20: Entrümpelung | D20: Handwerk/Bau | E20: Hüttenbergstr. 25, 66538 Neunkirchen | F20: 0170 4 42 45 32 | G20: https://ruempel-alf.de/ | H20: live | I20: ja | J20: nein | K20: 16.3 | L20: WordPress 7.1.3 | N20: nein | O20: nein | P20: nein | Q20: nein | R20: 4.9 | S20: 218 | T20: 21 | U20: 16 | V20: 22 | W20: 10 | X20: =SUM(T20:W20) -> 69 | Y20: Quick Win | Z20: Liste 2 | AA20: Aref Al Faroukh | AB20: post@ruempel-alf.de | AC20: https://ruempel-alf.de/impressum/
A21: 20 | B21: Sascha Kieczewsky Planungsbüro | C21: Planungsbüro | D21: Handel/Dienstleistung | E21: Schulstr. 17 A, 66540 Neunkirchen | F21: 06858 5 99 90 54 | G21: https://pbm-muenchwies.de/cgi-sys/suspendedpage.cgi | H21: live | I21: ja | J21: ja | K21: 1.6 | N21: nein | O21: nein | P21: nein | Q21: nein | T21: 30 | U21: 16 | V21: 12 | W21: 10 | X21: =SUM(T21:W21) -> 68 | Y21: Quick Win | Z21: Liste 2
A22: 21 | B22: Reitverein Neunkirchen-City | C22: Reitstall | D22: Freizeit/Sport/Kurse | E22: Betzenhölle 12, 66538 Neunkirchen | F22: 0170 9978064 | G22: https://reitverein-neunkirchencity.de/ | H22: live | I22: ja | J22: ja | K22: 2.1 | N22: nein | O22: nein | P22: nein | Q22: nein | T22: 30 | U22: 13 | V22: 15 | W22: 10 | X22: =SUM(T22:W22) -> 68 | Y22: Solide Chance | Z22: Liste 2
A23: 22 | B23: Markt Apotheke | C23: Apotheke | D23: Apotheke | E23: Max-Braun-Str. 1, 66538 Neunkirchen | F23: 06821 21811 | G23: https://www.markt-apotheke-nk.de/ | H23: live | I23: ja | J23: ja | K23: 9 | N23: nein | O23: nein | P23: nein | Q23: ja | R23: 4.8 | S23: 56 | T23: 29 | U23: 13 | V23: 19 | W23: 7 | X23: =SUM(T23:W23) -> 68 | Y23: Solide Chance | Z23: Liste 1 | AA23: Susanne Daniels | AB23: info@markt-apotheke-nk.de | AC23: https://www.markt-apotheke-nk.de/Impressum/
A24: 23 | B24: Regitz Kreativdesign | C24: Innenausbau | D24: Handwerk/Bau | E24: Homburger Str. 52, 66539 Neunkirchen | F24: 06821 8 96 05 | G24: https://www.regitz-creativ-design.de/ | H24: live | I24: ja | J24: nein | K24: 2.7 | L24: Ulli Meybohms HTML EDITOR | M24: Sat, 09 Jul 2022 23:11:34 GMT | N24: nein | O24: nein | P24: nein | Q24: nein | T24: 29 | U24: 16 | V24: 13 | W24: 10 | X24: =SUM(T24:W24) -> 68 | Y24: Quick Win | Z24: Liste 2
A25: 24 | B25: Horst Sehte GmbH | C25: Dachdecker | D25: Handwerk/Bau | E25: Schillerstr. 49, 66540 Neunkirchen | F25: 06821 5 13 56 | G25: https://dach-sehte.de/ | H25: live | I25: ja | J25: ja | K25: 3.7 | L25: Nicepage 8.5.1, nicepage.com | M25: Fri, 10 Jul 2026 09:32:24 GMT | N25: nein | O25: nein | P25: nein | Q25: nein | R25: 4.4 | S25: 40 | T25: 28 | U25: 16 | V25: 14 | W25: 10 | X25: =SUM(T25:W25) -> 68 | Y25: Quick Win | Z25: Liste 2 | AA25: Michael Sehte | AB25: info@dach-sehte.de
A26: 25 | B26: Elektro Hobler UG (haftungsbeschränkt) Elektroinstallationen | C26: Elektriker | D26: Handwerk/Bau | E26: Martin-Luther-Str. 19, 66540 Neunkirchen | F26: 06821 95 20 63 | G26: https://www.elektro-hobler.de/ | H26: live | I26: ja | J26: nein | K26: 4.4 | L26: IONOS MyWebsite | N26: nein | O26: nein | P26: nein | Q26: nein | R26: 4.3 | S26: 17 | T26: 25 | U26: 16 | V26: 14 | W26: 13 | X26: =SUM(T26:W26) -> 68 | Y26: Quick Win | Z26: Liste 2 | AB26: info@elektro-hobler.de | AC26: https://www.elektro-hobler.de/impressum/
A27: 26 | B27: VSV Hochbau GmbH | C27: Bauunternehmen/Abbruch | D27: Handwerk/Bau | E27: Wellesweilerstr. 86, 66538 Neunkirchen | F27: 06821 59 07 21 | G27: https://www.vsv-abbruch.de/ | H27: live | I27: ja | J27: nein | K27: 4.6 | L27: 2018.1.1.386 | M27: Fri, 08 Mar 2024 11:41:34 GMT | N27: nein | O27: nein | P27: nein | Q27: nein | T27: 25 | U27: 16 | V27: 17 | W27: 10 | X27: =SUM(T27:W27) -> 68 | Y27: Quick Win | Z27: Liste 2 | AA27: Antonino Vullo | AB27: info@vsv-abbruch.de | AC27: https://www.vsv-abbruch.de/impressum.html
A28: 27 | B28: Asia Haus Thaimassagen | C28: Massagestudio | D28: Beauty/Körperpflege | E28: Kuchenbergstr. 109, 66540 Neunkirchen | F28: 06821 3 08 71 86 | G28: https://www.thaimassage-asiahaus.de/ | H28: live | I28: ja | J28: nein | K28: 10.8 | L28: WordPress 4.9.26 | N28: ja | O28: nein | P28: nein | Q28: nein | R28: 4.7 | S28: 125 | T28: 27 | U28: 17 | V28: 17 | W28: 6 | X28: =SUM(T28:W28) -> 67 | Y28: Quick Win | Z28: Liste 2 | AC28: http://www.thaimassage-asiahaus.de/impressum
A29: 28 | B29: Koble-Tassone Jeannine Friseur | C29: Friseur | D29: Beauty/Körperpflege | E29: Kuchenbergstr. 1, 66540 Neunkirchen | F29: 06821 9 83 84 60 | G29: https://www.koble-hair.de/ | H29: live | I29: ja | J29: nein | K29: 3.2 | M29: Mon, 27 May 2024 06:34:55 GMT | N29: nein | O29: nein | P29: nein | Q29: nein | R29: 4.3 | S29: 6 | T29: 24 | U29: 17 | V29: 13 | W29: 13 | X29: =SUM(T29:W29) -> 67 | Y29: Quick Win | Z29: Liste 2 | AA29: Jeannine Koble-Tassone | AB29: info@koble-hair.de | AC29: https://www.koble-hair.de/impressum.html
A30: 29 | B30: Wirtshaus Römer Steakhaus | C30: Restaurant | D30: Gastronomie | E30: Bahnhofstr. 5, 66538 Neunkirchen | F30: 06821 942756 | G30: https://www.wirtshaus-roemer.de/ | H30: live | I30: ja | J30: ja | K30: 5.9 | L30: Joomla! - Open Source Content | M30: Fri, 09 Oct 2026 17:14:30 GMT | N30: nein | O30: nein | P30: nein | Q30: ja | R30: 4.1 | S30: 364 | T30: 21 | U30: 15 | V30: 24 | W30: 7 | X30: =SUM(T30:W30) -> 67 | Y30: Umsatzhebel | Z30: Liste 1 | AA30: Alevtina Hau | AB30: info@wirtshaus-roemer.de | AC30: https://www.wirtshaus-roemer.de/impressum
A31: 30 | B31: Damaskus Haus | C31: Imbiss/Restaurant | D31: Lieferdienst/Imbiss | E31: Bahnhofstr. 39, 66538 Neunkirchen | F31: 06821 149263 | G31: https://www.damaskus-haus-neunkirchen.de/ | H31: live | I31: ja | J31: ja | K31: 12.1 | N31: nein | O31: nein | P31: nein | Q31: ja | R31: 3.7 | S31: 165 | T31: 18 | U31: 12 | V31: 25 | W31: 12 | X31: =SUM(T31:W31) -> 67 | Y31: Umsatzhebel | Z31: Liste 1 | AC31: https://www.damaskus-haus-neunkirchen.de/colofon
A32: 31 | B32: Schneider Birgit Musikunterricht | C32: Musikschule | D32: Freizeit/Sport/Kurse | E32: Eisenbahnstr. 51, 66539 Neunkirchen | F32: 06821 4 21 84 | G32: https://www.musikunterricht-neunkirchen.de/ | H32: live | I32: ja | J32: nein | K32: 8.4 | N32: nein | O32: nein | P32: nein | Q32: nein | T32: 28 | U32: 15 | V32: 13 | W32: 10 | X32: =SUM(T32:W32) -> 66 | Y32: Quick Win | Z32: Liste 2 | AA32: Birgit Schneider | AB32: musik.schneider@t-online.de | AC32: https://www.musikunterricht-neunkirchen.de/Impressum
A33: 32 | B33: DIVNA Medizinische Fußpflege | C33: Podologie | D33: Praxis/Gesundheit | E33: Hermannstr. 53, 66538 Neunkirchen | F33: 06821 98 31 90 | G33: https://www.podologie-divna.de/ | H33: live | I33: ja | J33: nein | K33: 3.9 | M33: Wed, 11 Jul 2018 08:35:02 GMT | N33: nein | O33: nein | P33: nein | Q33: nein | R33: 4.6 | S33: 37 | T33: 27 | U33: 13 | V33: 15 | W33: 10 | X33: =SUM(T33:W33) -> 65 | Y33: Solide Chance | Z33: Liste 2 | AC33: https://www.podologie-divna.de/impressum.html
A34: 33 | B34: Orthopädie Lattrich GmbH Wolfgang | C34: Sanitätshaus/Orthopädietechnik | D34: Praxis/Gesundheit | E34: Hebbelstr. 5-7, 66538 Neunkirchen | F34: 06821 2 24 76 | G34: https://lattrich.de/ | H34: live | I34: ja | J34: ja | K34: 10 | L34: Joomla! - Open Source Content | M34: Mon, 19 Oct 2026 00:12:00 GMT | N34: nein | O34: nein | P34: nein | Q34: nein | R34: 4 | S34: 35 | T34: 25 | U34: 13 | V34: 17 | W34: 10 | X34: =SUM(T34:W34) -> 65 | Y34: Solide Chance | Z34: Liste 2 | AA34: Jörg Lattrich | AB34: info@lattrich.de | AC34: https://lattrich.de/index.php?option=com_content&view=article&id=4&Itemid=105
A35: 34 | B35: DEJA Vu Second Hand Exclusive | C35: Mode (Second Hand) | D35: Handel/Dienstleistung | E35: Hüttenbergstr. 37, 66538 Neunkirchen | F35: 06821 2 31 14 | G35: https://deja-vu-exclusiv.de/ | H35: live | I35: ja | J35: ja | K35: 10.1 | L35: WordPress 7.0.7 | N35: nein | O35: nein | P35: nein | Q35: nein | R35: 4.1 | S35: 57 | T35: 20 | U35: 16 | V35: 19 | W35: 10 | X35: =SUM(T35:W35) -> 65 | Y35: Quick Win | Z35: Liste 2 | AA35: Friedel Ludes | AB35: info@deja-vu-exclusiv.de | AC35: https://deja-vu-exclusiv.de/impressum/
A36: 35 | B36: Schmidt Thomas Michael Dr.med. u. Schmitt Kerstin Dr.med. | C36: Hausarzt | D36: Praxis/Gesundheit | E36: Winterfloß 17, 66539 Neunkirchen | F36: 06821 43 11 | G36: https://www.praxis-wellesweiler.de/ | H36: live | I36: ja | J36: nein | K36: 6.3 | N36: nein | O36: nein | P36: nein | Q36: ja | T36: 32 | U36: 13 | V36: 12 | W36: 7 | X36: =SUM(T36:W36) -> 64 | Y36: Solide Chance | Z36: Liste 2 | AB36: info@praxis-wellesweiler.de | AC36: https://www.praxis-wellesweiler.de/impressum-und-datenschutz
A37: 36 | B37: König Bernd Dipl.-Ing. Architekt | C37: Architekt | D37: Beratung/Kanzlei | E37: Spieser Str. 94, 66538 Neunkirchen | F37: 06821 8 87 57 | G37: https://www.architekt-bernd-koenig.de/ | H37: live | I37: ja | J37: ja | K37: 1.4 | N37: nein | O37: nein | P37: nein | Q37: nein | T37: 30 | U37: 12 | V37: 12 | W37: 10 | X37: =SUM(T37:W37) -> 64 | Y37: Langläufer | Z37: Liste 2
A38: 37 | B38: Arminia Steuerberatung | C38: Steuerberater | D38: Beratung/Kanzlei | E38: Goethestr. 12, 66538 Neunkirchen | F38: 06821 999720 | G38: https://www.arminia-steuerberatung.de/ | H38: live | I38: ja | J38: nein | K38: 15.5 | M38: Tue, 31 Mar 2026 12:32:08 GMT | N38: nein | O38: nein | P38: nein | Q38: nein | R38: 5 | S38: 1 | T38: 28 | U38: 10 | V38: 13 | W38: 13 | X38: =SUM(T38:W38) -> 64 | Y38: Langläufer | Z38: Liste 1 | AB38: info@arminia-steuerberatung.de | AC38: https://www.arminia-steuerberatung.de/#slide6
A39: 38 | B39: Decker Fenster Haustüren Rollladen GmbH | C39: Fenster/Türen/Rollladen | D39: Handwerk/Bau | E39: Ludwigsthaler Str. 1, 66539 Neunkirchen | F39: 06821 36 15 24 | G39: https://www.decker-fenster.de/ | H39: live | I39: ja | J39: nein | K39: 4.7 | L39: Joomla! - Open Source Content | M39: Mon, 19 Oct 2026 00:08:53 GMT | N39: nein | O39: nein | P39: nein | Q39: nein | R39: 4.1 | S39: 33 | T39: 24 | U39: 16 | V39: 14 | W39: 10 | X39: =SUM(T39:W39) -> 64 | Y39: Quick Win | Z39: Liste 2 | AA39: Detlef Decker | AB39: info@decker-fenster.de | AC39: https://www.decker-fenster.de/impressum
A40: 39 | B40: LOGOPÄDIE Krämer Monika Schwochow Nathalie | C40: Logopädie | D40: Praxis/Gesundheit | E40: Hebbelstr. 15, 66538 Neunkirchen | F40: 06821 6 30 68 06 | G40: https://www.logopaedie-neunkirchen.de/ | H40: live | I40: ja | J40: nein | K40: 5.7 | N40: nein | O40: nein | P40: nein | Q40: nein | R40: 5 | S40: 5 | T40: 23 | U40: 13 | V40: 15 | W40: 13 | X40: =SUM(T40:W40) -> 64 | Y40: Solide Chance | Z40: Liste 2 | AB40: info@logopaedie-neunkirchen.de | AC40: https://www.logopaedie-neunkirchen.de/?/impressum
...

Sheet Outreach
A1: Rang | B1: Betrieb | C1: Welle | D1: Segment | E1: Inhaber/in | F1: Anrede | G1: Straße, PLZ Ort | H1: Telefon | I1: E-Mail (nur nach Einwilligung) | J1: Domain | K1: Aufhänger 1 | L1: Aufhänger 2 (P.S.) | M1: Winkel | N1: Extra | O1: Preis | P1: Monat | Q1: Ziel | R1: Tipp | S1: Vorlage Brief | T1: Vorschau-Link (optional) | U1: Betreff Brief | V1: Brief-Text | W1: Mail nach Besuch (M1) | X1: Nachfassen Tag 3 (F1) | Y1: Nachfassen Tag 7 (F2) | Z1: Nachfassen Tag 14 (F3) | AA1: WhatsApp (W1) | AB1: Kanal | AC1: Datum Erstkontakt | AD1: Status | AE1: Nächster Schritt fällig | AF1: Notiz | AG1: Score | AH1: Label
A2: 1 | B2: Asia Wok Bistro | C2: 1 | D2: Gastronomie | F2: Guten Tag, | G2: Brückenstr. 26, 66538 Neunkirchen | H2: 06821 140373 | J2: asia-restaurant-neunkirchen.de | K2: Ihre Seite ist nicht für Smartphones angepasst. Auf dem Handy erscheint sie stark verkleinert, man muss zoomen, um etwas zu lesen. | L2: Sie haben 230 Google-Bewertungen mit 4,4 Sternen. Auf Ihrer Website sieht man davon nichts. | M2: Gäste suchen abends auf dem Handy nach Speisekarte, Öffnungszeiten und einem Platz für heute. | N2: eine Online-Reservierung und eine Seite für Feiern und Gruppen | O2: ab 990 € | P2: ab 39 € | Q2: mehr Reservierungen | R2: Laden Sie im Google-Unternehmensprofil fünf aktuelle Fotos hoch: ein Gericht, den Gastraum, die Außenansicht, das Team, die Theke. Google empfiehlt selbst, Fotos regelmäßig zu erneuern. | S2: B2 | U2: =SUBSTITUTE(SUBSTITUTE(SUBSTITUTE(SUBSTITUTE(SUBSTITUTE(SUBSTITUTE(SUBSTITUTE(SUBSTITUTE(SUBSTITUTE(SUBSTITUTE(SUBSTITUTE(SUBSTITUTE(SUBSTITUTE(SUBSTITUTE(SUBSTITUTE(SUBSTITUTE(SUBSTITUTE(INDEX(Vorlagen!$E:$E,MATCH($S2,Vorlagen!$A:$A,0)),"{Anrede}",$F2),"{Betrieb}",$B2),"{Domain}",$J2),"{Hook1}",$K2),"{Hook2}",$L2),"{Winkel}",$M2),"{Extra}",$N2),"{Preis}",$O2),"{Monat}",$P2),"{Ziel}",$Q2),"{Tipp}",$R2),"{Vorschau_Link}",IF($T2="",S_Vorschau_Link,$T2)),"{Absender}",S_Absender),"{Absender_Web}",S_Absender_Web),"{Telefon}",S_Telefon),"{Termin_Vorschlag}",S_Termin_Vorschlag),"{Referenzpreis_Datum}",S_Referenzpreis_Datum) -> Asia Wok Bistro: so könnte Ihre Website aussehen | V2: =SUBSTITUTE(SUBSTITUTE(SUBSTITUTE(SUBSTITUTE(SUBSTITUTE(SUBSTITUTE(SUBSTITUTE(SUBSTITUTE(SUBSTITUTE(SUBSTITUTE(SUBSTITUTE(SUBSTITUTE(SUBSTITUTE(SUBSTITUTE(SUBSTITUTE(SUBSTITUTE(SUBSTITUTE(INDEX(Vorlagen!$F:$F,MATCH($S2,Vorlagen!$A:$A,0)),"{Anrede}",$F2),"{Betrieb}",$B2),"{Domain}",$J2),"{Hook1}",$K2),"{Hook2}",$L2),"{Winkel}",$M2),"{Extra}",$N2),"{Preis}",$O2),"{Monat}",$P2),"{Ziel}",$Q2),"{Tipp}",$R2),"{Vorschau_Link}",IF($T2="",S_Vorschau_Link,$T2)),"{Absender}",S_Absender),"{Absender_Web}",S_Absender_Web),"{Telefon}",S_Telefon),"{Termin_Vorschlag}",S_Termin_Vorschlag),"{Referenzpreis_Datum}",S_Referenzpreis_Datum) -> Guten Tag, ich bin Jean, Webdesigner und KI-Berater hier in Neunkirchen. Ich habe Ihre Startseite einmal neu gestaltet, mit Ihren eigenen Texten und Fotos. Das Ergebnis liegt bei: links Ihre Seite heute, rechts der Entwurf. Warum ich mich melde: Ihre Seite ist nicht für Smartphones angepasst. Auf dem Handy erscheint sie stark verkleinert, man muss zoomen, um etwas zu lesen. Gäste suchen abends auf dem Handy nach Speisekarte, Öffnungszeiten und einem Platz für heute. Der Entwurf ist fertig. Ob Sie ihn nutzen, entscheiden Sie. Wenn Sie ihn auf Ihrem Handy sehen möchten, scannen Sie den QR-Code oder schreiben Sie mir per WhatsApp an . Ich komme auch gern für 15 Minuten vorbei. Damit Sie nicht raten müssen: ab 990 € einmalig, Betreuung ab 39 € im Monat. Die zweite Hälfte zahlen Sie erst, wenn die Seite online ist und Ihnen gefällt. Viele Grüße aus Neunkirchen Jean P.S. Sie haben 230 Google-Bewertungen mit 4,4 Sternen. Auf Ihrer Website sieht man davon nichts. Ihre Anschrift stammt aus Ihrem Impressum bzw. öffentlichen Branchenverzeichnissen. Wenn Sie keine Post mehr von mir möchten, genügt ein kurzer Hinweis. | W2: =SUBSTITUTE(SUBSTITUTE(SUBSTITUTE(SUBSTITUTE(SUBSTITUTE(SUBSTITUTE(SUBSTITUTE(SUBSTITUTE(SUBSTITUTE(SUBSTITUTE(SUBSTITUTE(SUBSTITUTE(SUBSTITUTE(SUBSTITUTE(SUBSTITUTE(SUBSTITUTE(SUBSTITUTE(Vorlagen!$F$5,"{Anrede}",$F2),"{Betrieb}",$B2),"{Domain}",$J2),"{Hook1}",$K2),"{Hook2}",$L2),"{Winkel}",$M2),"{Extra}",$N2),"{Preis}",$O2),"{Monat}",$P2),"{Ziel}",$Q2),"{Tipp}",$R2),"{Vorschau_Link}",IF($T2="",S_Vorschau_Link,$T2)),"{Absender}",S_Absender),"{Absender_Web}",S_Absender_Web),"{Telefon}",S_Telefon),"{Termin_Vorschlag}",S_Termin_Vorschlag),"{Referenzpreis_Datum}",S_Referenzpreis_Datum) -> Guten Tag, danke für die paar Minuten heute. Wie besprochen hier die Vorschau für Asia Wok Bistro: Öffnen Sie sie am besten auf dem Handy, so sehen Ihre Kunden die Seite auch. Kurz zusammengefasst: - Heute: Ihre Seite ist nicht für Smartphones angepasst. Auf dem Handy erscheint sie stark verkleinert, man muss zoomen, um etwas zu lesen. - Neu: Alles ist auf das Handy ausgelegt, dazu eine Online-Reservierung und eine Seite für Feiern und Gruppen. - Ihre Inhalte bleiben. Sie müssen nichts neu schreiben. Preis: ab 990 € einmalig, Betreuung ab 39 € im Monat. Die zweite Hälfte zahlen Sie erst nach dem Livegang. Nächster Schritt: 15 Minuten, in denen wir Fotos und zwei, drei Wünsche durchgehen. Passt Ihnen Donnerstag gegen 15 Uhr? Viele Grüße Jean Wenn Sie keine weiteren Nachrichten von mir möchten, genügt eine kurze Antwort. | X2: =SUBSTITUTE(SUBSTITUTE(SUBSTITUTE(SUBSTITUTE(SUBSTITUTE(SUBSTITUTE(SUBSTITUTE(SUBSTITUTE(SUBSTITUTE(SUBSTITUTE(SUBSTITUTE(SUBSTITUTE(SUBSTITUTE(SUBSTITUTE(SUBSTITUTE(SUBSTITUTE(SUBSTITUTE(Vorlagen!$F$7,"{Anrede}",$F2),"{Betrieb}",$B2),"{Domain}",$J2),"{Hook1}",$K2),"{Hook2}",$L2),"{Winkel}",$M2),"{Extra}",$N2),"{Preis}",$O2),"{Monat}",$P2),"{Ziel}",$Q2),"{Tipp}",$R2),"{Vorschau_Link}",IF($T2="",S_Vorschau_Link,$T2)),"{Absender}",S_Absender),"{Absender_Web}",S_Absender_Web),"{Telefon}",S_Telefon),"{Termin_Vorschlag}",S_Termin_Vorschlag),"{Referenzpreis_Datum}",S_Referenzpreis_Datum) -> Guten Tag, kurz nachgefragt: Konnten Sie die Vorschau schon auf dem Handy ansehen? Wenn Sie mögen, setze ich bis Ende der Woche Ihre eigenen Fotos ein. Dann sehen Sie die Seite so, wie sie online gehen würde. Ein kurzes "Ja, machen" genügt. Viele Grüße Jean Wenn Sie keine weiteren Nachrichten von mir möchten, genügt eine kurze Antwort. | Y2: =SUBSTITUTE(SUBSTITUTE(SUBSTITUTE(SUBSTITUTE(SUBSTITUTE(SUBSTITUTE(SUBSTITUTE(SUBSTITUTE(SUBSTITUTE(SUBSTITUTE(SUBSTITUTE(SUBSTITUTE(SUBSTITUTE(SUBSTITUTE(SUBSTITUTE(SUBSTITUTE(SUBSTITUTE(Vorlagen!$F$8,"{Anrede}",$F2),"{Betrieb}",$B2),"{Domain}",$J2),"{Hook1}",$K2),"{Hook2}",$L2),"{Winkel}",$M2),"{Extra}",$N2),"{Preis}",$O2),"{Monat}",$P2),"{Ziel}",$Q2),"{Tipp}",$R2),"{Vorschau_Link}",IF($T2="",S_Vorschau_Link,$T2)),"{Absender}",S_Absender),"{Absender_Web}",S_Absender_Web),"{Telefon}",S_Telefon),"{Termin_Vorschlag}",S_Termin_Vorschlag),"{Referenzpreis_Datum}",S_Referenzpreis_Datum) -> Guten Tag, unabhängig davon, ob wir zusammenarbeiten, hier ein Tipp, der in fünf Minuten erledigt ist: Laden Sie im Google-Unternehmensprofil fünf aktuelle Fotos hoch: ein Gericht, den Gastraum, die Außenansicht, das Team, die Theke. Google empfiehlt selbst, Fotos regelmäßig zu erneuern. Die Vorschau Ihrer neuen Seite liegt weiter für Sie bereit: Bei Fragen rufen Sie mich einfach an: Viele Grüße Jean Wenn Sie keine weiteren Nachrichten von mir möchten, genügt eine kurze Antwort. | Z2: =SUBSTITUTE(SUBSTITUTE(SUBSTITUTE(SUBSTITUTE(SUBSTITUTE(SUBSTITUTE(SUBSTITUTE(SUBSTITUTE(SUBSTITUTE(SUBSTITUTE(SUBSTITUTE(SUBSTITUTE(SUBSTITUTE(SUBSTITUTE(SUBSTITUTE(SUBSTITUTE(SUBSTITUTE(Vorlagen!$F$9,"{Anrede}",$F2),"{Betrieb}",$B2),"{Domain}",$J2),"{Hook1}",$K2),"{Hook2}",$L2),"{Winkel}",$M2),"{Extra}",$N2),"{Preis}",$O2),"{Monat}",$P2),"{Ziel}",$Q2),"{Tipp}",$R2),"{Vorschau_Link}",IF($T2="",S_Vorschau_Link,$T2)),"{Absender}",S_Absender),"{Absender_Web}",S_Absender_Web),"{Telefon}",S_Telefon),"{Termin_Vorschlag}",S_Termin_Vorschlag),"{Referenzpreis_Datum}",S_Referenzpreis_Datum) -> Guten Tag, ich möchte Ihr Postfach nicht füllen, deshalb ist das meine letzte Nachricht dazu. Den Referenzpreis halte ich für Sie bis 30.11.2026. Danach nehme ich die Vorschau aus dem Netz. Eine Ziffer als Antwort genügt mir: 1 = Ja, lassen Sie uns kurz sprechen 2 = Später, melden Sie sich im neuen Jahr 3 = Kein Interesse Danke und viele Grüße Jean | AA2: =SUBSTITUTE(SUBSTITUTE(SUBSTITUTE(SUBSTITUTE(SUBSTITUTE(SUBSTITUTE(SUBSTITUTE(SUBSTITUTE(SUBSTITUTE(SUBSTITUTE(SUBSTITUTE(SUBSTITUTE(SUBSTITUTE(SUBSTITUTE(SUBSTITUTE(SUBSTITUTE(SUBSTITUTE(Vorlagen!$F$10,"{Anrede}",$F2),"{Betrieb}",$B2),"{Domain}",$J2),"{Hook1}",$K2),"{Hook2}",$L2),"{Winkel}",$M2),"{Extra}",$N2),"{Preis}",$O2),"{Monat}",$P2),"{Ziel}",$Q2),"{Tipp}",$R2),"{Vorschau_Link}",IF($T2="",S_Vorschau_Link,$T2)),"{Absender}",S_Absender),"{Absender_Web}",S_Absender_Web),"{Telefon}",S_Telefon),"{Termin_Vorschlag}",S_Termin_Vorschlag),"{Referenzpreis_Datum}",S_Referenzpreis_Datum) -> Hallo, hier ist Jean von vorhin. Hier die Vorschau für Asia Wok Bistro, am besten gleich auf dem Handy öffnen: Ich melde mich Donnerstag gegen 15 Uhr kurz wegen der Fotos. Viele Grüße | AD2: offen | AE2: =IF(OR($AC2="",$AD2="Auftrag",$AD2="Abgesagt"),"",IF($AD2="Brief versendet",$AC2+5,IF($AD2="Vorschau gesendet",$AC2+3,IF($AD2="Nachgefasst 1",$AC2+7,IF($AD2="Nachgefasst 2",$AC2+14,""))))) | AG2: 77 | AH2: Umsatzhebel
A3: 2 | B3: Schlüssel Thielen | C3: 1 | D3: Handel/Dienstleistung | F3: Guten Tag, | G3: Hüttenbergstr. 30, 66538 Neunkirchen | H3: 06821 22510 | I3: info@schluessel-thielen.de | J3: schluessel-thielen.de | K3: Auf dem Handy ist Ihre Seite breiter als der Bildschirm. Man muss seitlich wischen, um alles zu sehen. | L3: Auf Ihrer Startseite steht fast kein Text. Google kann dadurch kaum erkennen, was Sie anbieten. | M3: Kunden prüfen vor dem Weg in die Stadt kurz auf dem Handy, ob Sie haben, was sie suchen. | N3: eine Sortiments- und Aktionsseite, die Sie selbst pflegen | O3: ab 690 € | P3: ab 29 € | Q3: mehr Laufkundschaft | R3: Tragen Sie Ihre Samstags- und Feiertagszeiten im Google-Profil ein und laden Sie drei aktuelle Fotos vom Schaufenster hoch. | S3: B2 | U3: =SUBSTITUTE(SUBSTITUTE(SUBSTITUTE(SUBSTITUTE(SUBSTITUTE(SUBSTITUTE(SUBSTITUTE(SUBSTITUTE(SUBSTITUTE(SUBSTITUTE(SUBSTITUTE(SUBSTITUTE(SUBSTITUTE(SUBSTITUTE(SUBSTITUTE(SUBSTITUTE(SUBSTITUTE(INDEX(Vorlagen!$E:$E,MATCH($S3,Vorlagen!$A:$A,0)),"{Anrede}",$F3),"{Betrieb}",$B3),"{Domain}",$J3),"{Hook1}",$K3),"{Hook2}",$L3),"{Winkel}",$M3),"{Extra}",$N3),"{Preis}",$O3),"{Monat}",$P3),"{Ziel}",$Q3),"{Tipp}",$R3),"{Vorschau_Link}",IF($T3="",S_Vorschau_Link,$T3)),"{Absender}",S_Absender),"{Absender_Web}",S_Absender_Web),"{Telefon}",S_Telefon),"{Termin_Vorschlag}",S_Termin_Vorschlag),"{Referenzpreis_Datum}",S_Referenzpreis_Datum) -> Schlüssel Thielen: so könnte Ihre Website aussehen | V3: =SUBSTITUTE(SUBSTITUTE(SUBSTITUTE(SUBSTITUTE(SUBSTITUTE(SUBSTITUTE(SUBSTITUTE(SUBSTITUTE(SUBSTITUTE(SUBSTITUTE(SUBSTITUTE(SUBSTITUTE(SUBSTITUTE(SUBSTITUTE(SUBSTITUTE(SUBSTITUTE(SUBSTITUTE(INDEX(Vorlagen!$F:$F,MATCH($S3,Vorlagen!$A:$A,0)),"{Anrede}",$F3),"{Betrieb}",$B3),"{Domain}",$J3),"{Hook1}",$K3),"{Hook2}",$L3),"{Winkel}",$M3),"{Extra}",$N3),"{Preis}",$O3),"{Monat}",$P3),"{Ziel}",$Q3),"{Tipp}",$R3),"{Vorschau_Link}",IF($T3="",S_Vorschau_Link,$T3)),"{Absender}",S_Absender),"{Absender_Web}",S_Absender_Web),"{Telefon}",S_Telefon),"{Termin_Vorschlag}",S_Termin_Vorschlag),"{Referenzpreis_Datum}",S_Referenzpreis_Datum) -> Guten Tag, ich bin Jean, Webdesigner und KI-Berater hier in Neunkirchen. Ich habe Ihre Startseite einmal neu gestaltet, mit Ihren eigenen Texten und Fotos. Das Ergebnis liegt bei: links Ihre Seite heute, rechts der Entwurf. Warum ich mich melde: Auf dem Handy ist Ihre Seite breiter als der Bildschirm. Man muss seitlich wischen, um alles zu sehen. Kunden prüfen vor dem Weg in die Stadt kurz auf dem Handy, ob Sie haben, was sie suchen. Der Entwurf ist fertig. Ob Sie ihn nutzen, entscheiden Sie. Wenn Sie ihn auf Ihrem Handy sehen möchten, scannen Sie den QR-Code oder schreiben Sie mir per WhatsApp an . Ich komme auch gern für 15 Minuten vorbei. Damit Sie nicht raten müssen: ab 690 € einmalig, Betreuung ab 29 € im Monat. Die zweite Hälfte zahlen Sie erst, wenn die Seite online ist und Ihnen gefällt. Viele Grüße aus Neunkirchen Jean P.S. Auf Ihrer Startseite steht fast kein Text. Google kann dadurch kaum erkennen, was Sie anbieten. Ihre Anschrift stammt aus Ihrem Impressum bzw. öffentlichen Branchenverzeichnissen. Wenn Sie keine Post mehr von mir möchten, genügt ein kurzer Hinweis. | W3: =SUBSTITUTE(SUBSTITUTE(SUBSTITUTE(SUBSTITUTE(SUBSTITUTE(SUBSTITUTE(SUBSTITUTE(SUBSTITUTE(SUBSTITUTE(SUBSTITUTE(SUBSTITUTE(SUBSTITUTE(SUBSTITUTE(SUBSTITUTE(SUBSTITUTE(SUBSTITUTE(SUBSTITUTE(Vorlagen!$F$5,"{Anrede}",$F3),"{Betrieb}",$B3),"{Domain}",$J3),"{Hook1}",$K3),"{Hook2}",$L3),"{Winkel}",$M3),"{Extra}",$N3),"{Preis}",$O3),"{Monat}",$P3),"{Ziel}",$Q3),"{Tipp}",$R3),"{Vorschau_Link}",IF($T3="",S_Vorschau_Link,$T3)),"{Absender}",S_Absender),"{Absender_Web}",S_Absender_Web),"{Telefon}",S_Telefon),"{Termin_Vorschlag}",S_Termin_Vorschlag),"{Referenzpreis_Datum}",S_Referenzpreis_Datum) -> Guten Tag, danke für die paar Minuten heute. Wie besprochen hier die Vorschau für Schlüssel Thielen: Öffnen Sie sie am besten auf dem Handy, so sehen Ihre Kunden die Seite auch. Kurz zusammengefasst: - Heute: Auf dem Handy ist Ihre Seite breiter als der Bildschirm. Man muss seitlich wischen, um alles zu sehen. - Neu: Alles ist auf das Handy ausgelegt, dazu eine Sortiments- und Aktionsseite, die Sie selbst pflegen. - Ihre Inhalte bleiben. Sie müssen nichts neu schreiben. Preis: ab 690 € einmalig, Betreuung ab 29 € im Monat. Die zweite Hälfte zahlen Sie erst nach dem Livegang. Nächster Schritt: 15 Minuten, in denen wir Fotos und zwei, drei Wünsche durchgehen. Passt Ihnen Donnerstag gegen 15 Uhr? Viele Grüße Jean Wenn Sie keine weiteren Nachrichten von mir möchten, genügt eine kurze Antwort. | X3: =SUBSTITUTE(SUBSTITUTE(SUBSTITUTE(SUBSTITUTE(SUBSTITUTE(SUBSTITUTE(SUBSTITUTE(SUBSTITUTE(SUBSTITUTE(SUBSTITUTE(SUBSTITUTE(SUBSTITUTE(SUBSTITUTE(SUBSTITUTE(SUBSTITUTE(SUBSTITUTE(SUBSTITUTE(Vorlagen!$F$7,"{Anrede}",$F3),"{Betrieb}",$B3),"{Domain}",$J3),"{Hook1}",$K3),"{Hook2}",$L3),"{Winkel}",$M3),"{Extra}",$N3),"{Preis}",$O3),"{Monat}",$P3),"{Ziel}",$Q3),"{Tipp}",$R3),"{Vorschau_Link}",IF($T3="",S_Vorschau_Link,$T3)),"{Absender}",S_Absender),"{Absender_Web}",S_Absender_Web),"{Telefon}",S_Telefon),"{Termin_Vorschlag}",S_Termin_Vorschlag),"{Referenzpreis_Datum}",S_Referenzpreis_Datum) -> Guten Tag, kurz nachgefragt: Konnten Sie die Vorschau schon auf dem Handy ansehen? Wenn Sie mögen, setze ich bis Ende der Woche Ihre eigenen Fotos ein. Dann sehen Sie die Seite so, wie sie online gehen würde. Ein kurzes "Ja, machen" genügt. Viele Grüße Jean Wenn Sie keine weiteren Nachrichten von mir möchten, genügt eine kurze Antwort. | Y3: =SUBSTITUTE(SUBSTITUTE(SUBSTITUTE(SUBSTITUTE(SUBSTITUTE(SUBSTITUTE(SUBSTITUTE(SUBSTITUTE(SUBSTITUTE(SUBSTITUTE(SUBSTITUTE(SUBSTITUTE(SUBSTITUTE(SUBSTITUTE(SUBSTITUTE(SUBSTITUTE(SUBSTITUTE(Vorlagen!$F$8,"{Anrede}",$F3),"{Betrieb}",$B3),"{Domain}",$J3),"{Hook1}",$K3),"{Hook2}",$L3),"{Winkel}",$M3),"{Extra}",$N3),"{Preis}",$O3),"{Monat}",$P3),"{Ziel}",$Q3),"{Tipp}",$R3),"{Vorschau_Link}",IF($T3="",S_Vorschau_Link,$T3)),"{Absender}",S_Absender),"{Absender_Web}",S_Absender_Web),"{Telefon}",S_Telefon),"{Termin_Vorschlag}",S_Termin_Vorschlag),"{Referenzpreis_Datum}",S_Referenzpreis_Datum) -> Guten Tag, unabhängig davon, ob wir zusammenarbeiten, hier ein Tipp, der in fünf Minuten erledigt ist: Tragen Sie Ihre Samstags- und Feiertagszeiten im Google-Profil ein und laden Sie drei aktuelle Fotos vom Schaufenster hoch. Die Vorschau Ihrer neuen Seite liegt weiter für Sie bereit: Bei Fragen rufen Sie mich einfach an: Viele Grüße Jean Wenn Sie keine weiteren Nachrichten von mir möchten, genügt eine kurze Antwort. | Z3: =SUBSTITUTE(SUBSTITUTE(SUBSTITUTE(SUBSTITUTE(SUBSTITUTE(SUBSTITUTE(SUBSTITUTE(SUBSTITUTE(SUBSTITUTE(SUBSTITUTE(SUBSTITUTE(SUBSTITUTE(SUBSTITUTE(SUBSTITUTE(SUBSTITUTE(SUBSTITUTE(SUBSTITUTE(Vorlagen!$F$9,"{Anrede}",$F3),"{Betrieb}",$B3),"{Domain}",$J3),"{Hook1}",$K3),"{Hook2}",$L3),"{Winkel}",$M3),"{Extra}",$N3),"{Preis}",$O3),"{Monat}",$P3),"{Ziel}",$Q3),"{Tipp}",$R3),"{Vorschau_Link}",IF($T3="",S_Vorschau_Link,$T3)),"{Absender}",S_Absender),"{Absender_Web}",S_Absender_Web),"{Telefon}",S_Telefon),"{Termin_Vorschlag}",S_Termin_Vorschlag),"{Referenzpreis_Datum}",S_Referenzpreis_Datum) -> Guten Tag, ich möchte Ihr Postfach nicht füllen, deshalb ist das meine letzte Nachricht dazu. Den Referenzpreis halte ich für Sie bis 30.11.2026. Danach nehme ich die Vorschau aus dem Netz. Eine Ziffer als Antwort genügt mir: 1 = Ja, lassen Sie uns kurz sprechen 2 = Später, melden Sie sich im neuen Jahr 3 = Kein Interesse Danke und viele Grüße Jean | AA3: =SUBSTITUTE(SUBSTITUTE(SUBSTITUTE(SUBSTITUTE(SUBSTITUTE(SUBSTITUTE(SUBSTITUTE(SUBSTITUTE(SUBSTITUTE(SUBSTITUTE(SUBSTITUTE(SUBSTITUTE(SUBSTITUTE(SUBSTITUTE(SUBSTITUTE(SUBSTITUTE(SUBSTITUTE(Vorlagen!$F$10,"{Anrede}",$F3),"{Betrieb}",$B3),"{Domain}",$J3),"{Hook1}",$K3),"{Hook2}",$L3),"{Winkel}",$M3),"{Extra}",$N3),"{Preis}",$O3),"{Monat}",$P3),"{Ziel}",$Q3),"{Tipp}",$R3),"{Vorschau_Link}",IF($T3="",S_Vorschau_Link,$T3)),"{Absender}",S_Absender),"{Absender_Web}",S_Absender_Web),"{Telefon}",S_Telefon),"{Termin_Vorschlag}",S_Termin_Vorschlag),"{Referenzpreis_Datum}",S_Referenzpreis_Datum) -> Hallo, hier ist Jean von vorhin. Hier die Vorschau für Schlüssel Thielen, am besten gleich auf dem Handy öffnen: Ich melde mich Donnerstag gegen 15 Uhr kurz wegen der Fotos. Viele Grüße | AD3: offen | AE3: =IF(OR($AC3="",$AD3="Auftrag",$AD3="Abgesagt"),"",IF($AD3="Brief versendet",$AC3+5,IF($AD3="Vorschau gesendet",$AC3+3,IF($AD3="Nachgefasst 1",$AC3+7,IF($AD3="Nachgefasst 2",$AC3+14,""))))) | AG3: 76 | AH3: Quick Win
A4: 3 | B4: L.A.-Nails Nagelstudio | C4: 1 | D4: Beauty/Körperpflege | F4: Guten Tag, | G4: Stummplatz 1, 66538 Neunkirchen | H4: 06821 1 79 91 52 | J4: la-nails.de | K4: Unter Ihrer Domain erscheint derzeit nur eine geparkte Seite des Anbieters GoDaddy. | L4: Sie haben 48 Google-Bewertungen mit 4,3 Sternen. Auf Ihrer Website sieht man davon nichts. | M4: Neukundinnen und Neukunden suchen auf dem Handy und buchen dort, wo es am schnellsten geht. | N4: eine Online-Terminbuchung mit Erinnerung | O4: ab 690 € | P4: ab 29 € | Q4: mehr gebuchte Termine | R4: Fügen Sie in Ihrem Google-Profil Ihre Leistungen mit Preisen hinzu. Neukundinnen und Neukunden vergleichen genau das. | S4: B1 | U4: =SUBSTITUTE(SUBSTITUTE(SUBSTITUTE(SUBSTITUTE(SUBSTITUTE(SUBSTITUTE(SUBSTITUTE(SUBSTITUTE(SUBSTITUTE(SUBSTITUTE(SUBSTITUTE(SUBSTITUTE(SUBSTITUTE(SUBSTITUTE(SUBSTITUTE(SUBSTITUTE(SUBSTITUTE(INDEX(Vorlagen!$E:$E,MATCH($S4,Vorlagen!$A:$A,0)),"{Anrede}",$F4),"{Betrieb}",$B4),"{Domain}",$J4),"{Hook1}",$K4),"{Hook2}",$L4),"{Winkel}",$M4),"{Extra}",$N4),"{Preis}",$O4),"{Monat}",$P4),"{Ziel}",$Q4),"{Tipp}",$R4),"{Vorschau_Link}",IF($T4="",S_Vorschau_Link,$T4)),"{Absender}",S_Absender),"{Absender_Web}",S_Absender_Web),"{Telefon}",S_Telefon),"{Termin_Vorschlag}",S_Termin_Vorschlag),"{Referenzpreis_Datum}",S_Referenzpreis_Datum) -> L.A.-Nails Nagelstudio: Ihre Website auf dem Handy | V4: =SUBSTITUTE(SUBSTITUTE(SUBSTITUTE(SUBSTITUTE(SUBSTITUTE(SUBSTITUTE(SUBSTITUTE(SUBSTITUTE(SUBSTITUTE(SUBSTITUTE(SUBSTITUTE(SUBSTITUTE(SUBSTITUTE(SUBSTITUTE(SUBSTITUTE(SUBSTITUTE(SUBSTITUTE(INDEX(Vorlagen!$F:$F,MATCH($S4,Vorlagen!$A:$A,0)),"{Anrede}",$F4),"{Betrieb}",$B4),"{Domain}",$J4),"{Hook1}",$K4),"{Hook2}",$L4),"{Winkel}",$M4),"{Extra}",$N4),"{Preis}",$O4),"{Monat}",$P4),"{Ziel}",$Q4),"{Tipp}",$R4),"{Vorschau_Link}",IF($T4="",S_Vorschau_Link,$T4)),"{Absender}",S_Absender),"{Absender_Web}",S_Absender_Web),"{Telefon}",S_Telefon),"{Termin_Vorschlag}",S_Termin_Vorschlag),"{Referenzpreis_Datum}",S_Referenzpreis_Datum) -> Guten Tag, ich bin Jean, Webdesigner und KI-Berater hier in Neunkirchen. Ich habe mir la-nails.de auf dem Handy angesehen. Dabei ist mir aufgefallen: Unter Ihrer Domain erscheint derzeit nur eine geparkte Seite des Anbieters GoDaddy. Neukundinnen und Neukunden suchen auf dem Handy und buchen dort, wo es am schnellsten geht. Deshalb ein Vorschlag: Ich baue Ihnen eine Vorschau Ihrer neuen Startseite, mit Ihren eigenen Texten und Fotos. Das kostet Sie nichts und verpflichtet Sie zu nichts. Ich bringe sie vorbei, Sie schauen sie in Ruhe an. Gefällt sie Ihnen nicht, war es das. Ein kurzes Ja genügt: QR-Code scannen, anrufen oder per WhatsApp schreiben an . Falls Sie danach umsteigen möchten: Eine neue Website kostet bei mir ab 690 €, die Betreuung ab 29 € im Monat. Für Betriebe wie Ihren lohnt sich oft zusätzlich eine Online-Terminbuchung mit Erinnerung. Viele Grüße aus Neunkirchen Jean P.S. Sie haben 48 Google-Bewertungen mit 4,3 Sternen. Auf Ihrer Website sieht man davon nichts. Ihre Anschrift stammt aus Ihrem Impressum bzw. öffentlichen Branchenverzeichnissen. Wenn Sie keine Post mehr von mir möchten, genügt ein kurzer Hinweis. | W4: =SUBSTITUTE(SUBSTITUTE(SUBSTITUTE(SUBSTITUTE(SUBSTITUTE(SUBSTITUTE(SUBSTITUTE(SUBSTITUTE(SUBSTITUTE(SUBSTITUTE(SUBSTITUTE(SUBSTITUTE(SUBSTITUTE(SUBSTITUTE(SUBSTITUTE(SUBSTITUTE(SUBSTITUTE(Vorlagen!$F$5,"{Anrede}",$F4),"{Betrieb}",$B4),"{Domain}",$J4),"{Hook1}",$K4),"{Hook2}",$L4),"{Winkel}",$M4),"{Extra}",$N4),"{Preis}",$O4),"{Monat}",$P4),"{Ziel}",$Q4),"{Tipp}",$R4),"{Vorschau_Link}",IF($T4="",S_Vorschau_Link,$T4)),"{Absender}",S_Absender),"{Absender_Web}",S_Absender_Web),"{Telefon}",S_Telefon),"{Termin_Vorschlag}",S_Termin_Vorschlag),"{Referenzpreis_Datum}",S_Referenzpreis_Datum) -> Guten Tag, danke für die paar Minuten heute. Wie besprochen hier die Vorschau für L.A.-Nails Nagelstudio: Öffnen Sie sie am besten auf dem Handy, so sehen Ihre Kunden die Seite auch. Kurz zusammengefasst: - Heute: Unter Ihrer Domain erscheint derzeit nur eine geparkte Seite des Anbieters GoDaddy. - Neu: Alles ist auf das Handy ausgelegt, dazu eine Online-Terminbuchung mit Erinnerung. - Ihre Inhalte bleiben. Sie müssen nichts neu schreiben. Preis: ab 690 € einmalig, Betreuung ab 29 € im Monat. Die zweite Hälfte zahlen Sie erst nach dem Livegang. Nächster Schritt: 15 Minuten, in denen wir Fotos und zwei, drei Wünsche durchgehen. Passt Ihnen Donnerstag gegen 15 Uhr? Viele Grüße Jean Wenn Sie keine weiteren Nachrichten von mir möchten, genügt eine kurze Antwort. | X4: =SUBSTITUTE(SUBSTITUTE(SUBSTITUTE(SUBSTITUTE(SUBSTITUTE(SUBSTITUTE(SUBSTITUTE(SUBSTITUTE(SUBSTITUTE(SUBSTITUTE(SUBSTITUTE(SUBSTITUTE(SUBSTITUTE(SUBSTITUTE(SUBSTITUTE(SUBSTITUTE(SUBSTITUTE(Vorlagen!$F$7,"{Anrede}",$F4),"{Betrieb}",$B4),"{Domain}",$J4),"{Hook1}",$K4),"{Hook2}",$L4),"{Winkel}",$M4),"{Extra}",$N4),"{Preis}",$O4),"{Monat}",$P4),"{Ziel}",$Q4),"{Tipp}",$R4),"{Vorschau_Link}",IF($T4="",S_Vorschau_Link,$T4)),"{Absender}",S_Absender),"{Absender_Web}",S_Absender_Web),"{Telefon}",S_Telefon),"{Termin_Vorschlag}",S_Termin_Vorschlag),"{Referenzpreis_Datum}",S_Referenzpreis_Datum) -> Guten Tag, kurz nachgefragt: Konnten Sie die Vorschau schon auf dem Handy ansehen? Wenn Sie mögen, setze ich bis Ende der Woche Ihre eigenen Fotos ein. Dann sehen Sie die Seite so, wie sie online gehen würde. Ein kurzes "Ja, machen" genügt. Viele Grüße Jean Wenn Sie keine weiteren Nachrichten von mir möchten, genügt eine kurze Antwort. | Y4: =SUBSTITUTE(SUBSTITUTE(SUBSTITUTE(SUBSTITUTE(SUBSTITUTE(SUBSTITUTE(SUBSTITUTE(SUBSTITUTE(SUBSTITUTE(SUBSTITUTE(SUBSTITUTE(SUBSTITUTE(SUBSTITUTE(SUBSTITUTE(SUBSTITUTE(SUBSTITUTE(SUBSTITUTE(Vorlagen!$F$8,"{Anrede}",$F4),"{Betrieb}",$B4),"{Domain}",$J4),"{Hook1}",$K4),"{Hook2}",$L4),"{Winkel}",$M4),"{Extra}",$N4),"{Preis}",$O4),"{Monat}",$P4),"{Ziel}",$Q4),"{Tipp}",$R4),"{Vorschau_Link}",IF($T4="",S_Vorschau_Link,$T4)),"{Absender}",S_Absender),"{Absender_Web}",S_Absender_Web),"{Telefon}",S_Telefon),"{Termin_Vorschlag}",S_Termin_Vorschlag),"{Referenzpreis_Datum}",S_Referenzpreis_Datum) -> Guten Tag, unabhängig davon, ob wir zusammenarbeiten, hier ein Tipp, der in fünf Minuten erledigt ist: Fügen Sie in Ihrem Google-Profil Ihre Leistungen mit Preisen hinzu. Neukundinnen und Neukunden vergleichen genau das. Die Vorschau Ihrer neuen Seite liegt weiter für Sie bereit: Bei Fragen rufen Sie mich einfach an: Viele Grüße Jean Wenn Sie keine weiteren Nachrichten von mir möchten, genügt eine kurze Antwort. | Z4: =SUBSTITUTE(SUBSTITUTE(SUBSTITUTE(SUBSTITUTE(SUBSTITUTE(SUBSTITUTE(SUBSTITUTE(SUBSTITUTE(SUBSTITUTE(SUBSTITUTE(SUBSTITUTE(SUBSTITUTE(SUBSTITUTE(SUBSTITUTE(SUBSTITUTE(SUBSTITUTE(SUBSTITUTE(Vorlagen!$F$9,"{Anrede}",$F4),"{Betrieb}",$B4),"{Domain}",$J4),"{Hook1}",$K4),"{Hook2}",$L4),"{Winkel}",$M4),"{Extra}",$N4),"{Preis}",$O4),"{Monat}",$P4),"{Ziel}",$Q4),"{Tipp}",$R4),"{Vorschau_Link}",IF($T4="",S_Vorschau_Link,$T4)),"{Absender}",S_Absender),"{Absender_Web}",S_Absender_Web),"{Telefon}",S_Telefon),"{Termin_Vorschlag}",S_Termin_Vorschlag),"{Referenzpreis_Datum}",S_Referenzpreis_Datum) -> Guten Tag, ich möchte Ihr Postfach nicht füllen, deshalb ist das meine letzte Nachricht dazu. Den Referenzpreis halte ich für Sie bis 30.11.2026. Danach nehme ich die Vorschau aus dem Netz. Eine Ziffer als Antwort genügt mir: 1 = Ja, lassen Sie uns kurz sprechen 2 = Später, melden Sie sich im neuen Jahr 3 = Kein Interesse Danke und viele Grüße Jean | AA4: =SUBSTITUTE(SUBSTITUTE(SUBSTITUTE(SUBSTITUTE(SUBSTITUTE(SUBSTITUTE(SUBSTITUTE(SUBSTITUTE(SUBSTITUTE(SUBSTITUTE(SUBSTITUTE(SUBSTITUTE(SUBSTITUTE(SUBSTITUTE(SUBSTITUTE(SUBSTITUTE(SUBSTITUTE(Vorlagen!$F$10,"{Anrede}",$F4),"{Betrieb}",$B4),"{Domain}",$J4),"{Hook1}",$K4),"{Hook2}",$L4),"{Winkel}",$M4),"{Extra}",$N4),"{Preis}",$O4),"{Monat}",$P4),"{Ziel}",$Q4),"{Tipp}",$R4),"{Vorschau_Link}",IF($T4="",S_Vorschau_Link,$T4)),"{Absender}",S_Absender),"{Absender_Web}",S_Absender_Web),"{Telefon}",S_Telefon),"{Termin_Vorschlag}",S_Termin_Vorschlag),"{Referenzpreis_Datum}",S_Referenzpreis_Datum) -> Hallo, hier ist Jean von vorhin. Hier die Vorschau für L.A.-Nails Nagelstudio, am besten gleich auf dem Handy öffnen: Ich melde mich Donnerstag gegen 15 Uhr kurz wegen der Fotos. Viele Grüße | AD4: offen | AE4: =IF(OR($AC4="",$AD4="Auftrag",$AD4="Abgesagt"),"",IF($AD4="Brief versendet",$AC4+5,IF($AD4="Vorschau gesendet",$AC4+3,IF($AD4="Nachgefasst 1",$AC4+7,IF($AD4="Nachgefasst 2",$AC4+14,""))))) | AG4: 76 | AH4: Quick Win
